<?xml version="1.0" ?>
<!-- =================================================================================== -->
<!-- |    This document was autogenerated by xacro from /home/anish/arduino_bot/src/robot_arm_description/urdf/marty_arm.urdf.xacro | -->
<!-- |    EDITING THIS FILE BY HAND IS NOT RECOMMENDED                                 | -->
<!-- =================================================================================== -->
<robot name="rover">
    <link name="world" />
    <link name="base">
        <inertial>
            <mass value="5.96036834137502" />
            <inertia ixx="0.0137239871414956" ixy="2.3638667800933E-07" ixz="-0.000364311854125712" iyy="0.0269814949976083" iyz="-2.00027728952392E-06" izz="0.014279349996248" />
            <origin xyz="0 0 0" rpy="0 0 0" />
        </inertial>
        <visual>
            <origin rpy="1.57 0 0" xyz="-0.13 0 0" />
            <geometry>
                <mesh filename="package://robot_arm_description/mesh/Base_Assem_1.STL" scale="0.001 0.001 0.001" />
            </geometry>
        </visual>
        <collision>
            <origin rpy="1.57 0 0" xyz="-0.13 0 0" />
            <geometry>
                <mesh filename="package://robot_arm_description/mesh/Base_Assem_1.STL" scale="0.001 0.001 0.001" />
            </geometry>
        </collision>
    </link>
    <link name="base2">
        <inertial>
            <mass value="3.89596770051855" />
            <inertia ixx="0.0191021438712721" ixy="0.000738177788943129" ixz="0.0011681549752791" iyy="0.0264194098457387" iyz="-0.00253452919644933" izz="0.0154383525004192" />
            <origin xyz="0 0 0" rpy="0 0 0" />
        </inertial>
        <visual>
            <origin rpy="1.57 0 0" xyz="-0.11 -0.01 0.025" />
            <geometry>
                <mesh filename="package://robot_arm_description/mesh/BaseAct_Assem_2.STL" scale="0.001 0.001 0.001" />
            </geometry>
        </visual>
        <collision>
            <origin rpy="1.57 0 0" xyz="-0.11 -0.01 0.025" />
            <geometry>
                <mesh filename="package://robot_arm_description/mesh/BaseAct_Assem_2.STL" scale="0.001 0.001 0.001" />
            </geometry>
        </collision>
    </link>
    <link name="arm1">
        <inertial>
            <mass value="4.77720765960259" />
            <inertia ixx="0.168367641523994" ixy="-0.000944969125208024" ixz="6.74673054737673E-06" iyy="0.0122648958371462" iyz="-3.04543946683649E-05" izz="0.167124332468444" />
            <origin xyz="0 0 0" rpy="0 0 0" />
        </inertial>
        <visual>
            <origin rpy="0 1.57 1.57" xyz="0.035 -0.04 0.06" />
            <geometry>
                <mesh filename="package://robot_arm_description/mesh/link1_modified.STL" scale="0.001 0.001 0.001" />
            </geometry>
        </visual>
        <collision>
            <origin rpy="0 1.57 1.57" xyz="0.035 -0.04 0.06" />
            <geometry>
                <mesh filename="package://robot_arm_description/mesh/link1_modified.STL" scale="0.001 0.001 0.001" />
            </geometry>
        </collision>
    </link>
    <link name="arm2">
        <inertial>
            <mass value="1.3954149543627" />
            <inertia ixx="0.0341551992778207" ixy="3.3635594681094E-09" ixz="-9.94323089275709E-09" iyy="0.0340603075469231" iyz="0.000969678895230152" izz="0.00166894642902008" />
            <origin xyz="0 0 0" rpy="0 0 0" />
        </inertial>
        <visual>
            <origin rpy="0 1.57 1.57" xyz="0.04 -0.035 -0.035" />
            <geometry>
                <mesh filename="package://robot_arm_description/mesh/link2_assem.STL" scale="0.001 0.001 0.001" />
            </geometry>
        </visual>
        <collision>
            <origin rpy="0 1.57 1.57" xyz="0.04 -0.035 -0.035" />
            <geometry>
                <mesh filename="package://robot_arm_description/mesh/link2_assem.STL" scale="0.001 0.001 0.001" />
            </geometry>
        </collision>
    </link>
    <link name="arm3">
        <inertial>
            <mass value="0.53192129862332" />
            <inertia ixx="0.00186074557200856" ixy="1.06347960425329E-07" ixz="-7.97411659174863E-07" iyy="0.00186651438031198" iyz="0.000182892043883162" izz="0.000573407427302563" />
            <origin xyz="0 0 0" rpy="0 0 0" />
        </inertial>
        <visual>
            <origin rpy="3.14 1.57 1.57" xyz="-0.17 0.05 0.075" />
            <geometry>
                <mesh filename="package://robot_arm_description/mesh/link3_mod.STL" scale="0.001 0.001 0.001" />
            </geometry>
        </visual>
        <collision>
            <origin rpy="3.14 1.57 1.57" xyz="-0.17 0.05 0.075" />
            <geometry>
                <mesh filename="package://robot_arm_description/mesh/link3_mod.STL" scale="0.001 0.001 0.001" />
            </geometry>
        </collision>
    </link>
    <link name="gripper_arm_join">
        <inertial>
            <mass value="0.716925759354264" />
            <inertia ixx="0.000853308507486361" ixy="-0.000552251129474354" ixz="-2.46729187502994E-09" iyy="0.00108489827843447" iyz="6.82682593436447E-09" izz="0.00165199325783986" />
            <origin xyz="0 0 0" rpy="0 0 0" />
        </inertial>
        <visual>
            <origin rpy="1.57 1.45 1.57" xyz="-0.035 -0.022 0.035" />
            <geometry>
                <mesh filename="package://robot_arm_description/mesh/gripper_assem_mod.STL" scale="0.001 0.001 0.001" />
            </geometry>
        </visual>
        <collision>
            <origin rpy="1.57 1.45 1.57" xyz="-0.035 -0.022 0.035" />
            <geometry>
                <mesh filename="package://robot_arm_description/mesh/gripper_assem_mod.STL" scale="0.001 0.001 0.001" />
            </geometry>
        </collision>
    </link>
    <link name="gripper_left">
        <inertial>
            <mass value="0.197392232379841" />
            <inertia ixx="0.000451122398079037" ixy="3.98148365462816E-12" ixz="9.57839155740049E-06" iyy="0.000443471888198326" iyz="2.05364892251969E-11" izz="2.79034093029294E-05" />
            <origin xyz="0 0 0" rpy="0 0 0" />
        </inertial>
        <visual>
            <origin rpy="0 0 1.57" xyz="0.0375 0.030 -0.015" />
            <geometry>
                <mesh filename="package://robot_arm_description/mesh/Gripper Finger.STL" scale="0.001 0.001 0.001" />
            </geometry>
        </visual>
        <collision>
            <origin rpy="0 0 1.57" xyz="0.0375 0.030 -0.015" />
            <geometry>
                <mesh filename="package://robot_arm_description/mesh/Gripper Finger.STL" scale="0.001 0.001 0.001" />
            </geometry>
        </collision>
    </link>
    <link name="gripper_right">
        <inertial>
            <mass value="0.197392232379841" />
            <inertia ixx="0.000451122398079037" ixy="3.98148365462816E-12" ixz="9.57839155740049E-06" iyy="0.000443471888198326" iyz="2.05364892251969E-11" izz="2.79034093029294E-05" />
            <origin xyz="0 0 0" rpy="0 0 0" />
        </inertial>
        <visual>
            <origin rpy="3.14 0 -1.57" xyz="0.0375 -0.030 0.02" />
            <geometry>
                <mesh filename="package://robot_arm_description/mesh/Gripper Finger.STL" scale="0.001 0.001 0.001" />
            </geometry>
        </visual>
        <collision>
            <origin rpy="3.14 0 -1.57" xyz="0.0375 -0.030 0.02" />
            <geometry>
                <mesh filename="package://robot_arm_description/mesh/Gripper Finger.STL" scale="0.001 0.001 0.001" />
            </geometry>
        </collision>
    </link>
    <joint name="virtual_joint" type="fixed">
        <parent link="world" />
        <child link="base" />
        <origin rpy="0 0 0" xyz="0 0 0.0" />
    </joint>
    <joint name="joint1" type="revolute">
        <parent link="base" />
        <child link="base2" />
        <origin rpy="0 0 0" xyz="0 0 0.05" />
        <axis xyz="0 0 1" />
        <limit effort="30" lower="-3.14" upper="3.14" velocity="10" />
    </joint>
    <joint name="joint2" type="revolute">
        <parent link="base2" />
        <child link="arm1" />
        <origin rpy="0 0 0" xyz="-0.045 0 0.08" />
        <axis xyz="0 1 0" />
        <limit effort="30" lower="1.0466666666666666" upper="1.57" velocity="10" />
    </joint>
    <joint name="joint3" type="revolute">
        <parent link="arm1" />
        <child link="arm2" />
        <origin rpy="0 0 0" xyz="-0.53 0 -0.01" />
        <axis xyz="0 1 0" />
        <limit effort="30" lower="-0.785" upper="0.5233333333333333" velocity="10" />
    </joint>
    <joint name="joint4" type="revolute">
        <parent link="arm2" />
        <child link="arm3" />
        <origin rpy="0 0 0" xyz="-0.015 0 -0.42" />
        <axis xyz="0 1 0" />
        <limit effort="30" lower="-2.355" upper="-0.785" velocity="10" />
    </joint>
    <joint name="joint5" type="revolute">
        <parent link="arm3" />
        <child link="gripper_arm_join" />
        <origin rpy="0 0 0" xyz="-0.25 -0.005 -0.01" />
        <axis xyz="1 0 0" />
        <limit effort="30" lower="-3.14" upper="3.14" velocity="10" />
    </joint>
    <joint name="joint6" type="prismatic">
        <parent link="gripper_arm_join" />
        <child link="gripper_left" />
        <origin rpy="0 0 0" xyz="-0.025 0 0" />
        <axis xyz="0 1 0" />
        <limit effort="30" lower="0" upper="0.05" velocity="10" />
    </joint>
    <joint name="joint7" type="prismatic">
        <parent link="gripper_arm_join" />
        <child link="gripper_right" />
        <origin rpy="0 0 0" xyz="-0.025 0 0" />
        <axis xyz="0 1 0" />
        <limit effort="30" lower="-0.05" upper="0" velocity="10" />
        <mimic joint="joint6" multiplier="-1" offset="0" />
    </joint>
    <transmission name="transmission1">
        <type>transmission_interface/SimpleTransmission</type>
        <joint name="joint1">
            <hardwareInterface>hardware_interface/PositionJointInterface</hardwareInterface>
        </joint>
        <actuator name="motor1">
            <hardwareInterface>hardware_interface/PositionJointInterface</hardwareInterface>
            <mechanicalReduction>1</mechanicalReduction>
        </actuator>
    </transmission>
    <transmission name="transmission2">
        <type>transmission_interface/SimpleTransmission</type>
        <joint name="joint2">
            <hardwareInterface>hardware_interface/PositionJointInterface</hardwareInterface>
        </joint>
        <actuator name="motor2">
            <hardwareInterface>hardware_interface/PositionJointInterface</hardwareInterface>
            <mechanicalReduction>1</mechanicalReduction>
        </actuator>
    </transmission>
    <transmission name="transmission3">
        <type>transmission_interface/SimpleTransmission</type>
        <joint name="joint3">
            <hardwareInterface>hardware_interface/PositionJointInterface</hardwareInterface>
        </joint>
        <actuator name="motor3">
            <hardwareInterface>hardware_interface/PositionJointInterface</hardwareInterface>
            <mechanicalReduction>1</mechanicalReduction>
        </actuator>
    </transmission>
    <transmission name="transmission4">
        <type>transmission_interface/SimpleTransmission</type>
        <joint name="joint4">
            <hardwareInterface>hardware_interface/PositionJointInterface</hardwareInterface>
        </joint>
        <actuator name="motor4">
            <hardwareInterface>hardware_interface/PositionJointInterface</hardwareInterface>
            <mechanicalReduction>1</mechanicalReduction>
        </actuator>
    </transmission>
    <transmission name="transmission5">
        <type>transmission_interface/SimpleTransmission</type>
        <joint name="joint5">
            <hardwareInterface>hardware_interface/PositionJointInterface</hardwareInterface>
        </joint>
        <actuator name="motor5">
            <hardwareInterface>hardware_interface/PositionJointInterface</hardwareInterface>
            <mechanicalReduction>1</mechanicalReduction>
        </actuator>
    </transmission>
    <transmission name="transmission6">
        <type>transmission_interface/SimpleTransmission</type>
        <joint name="joint6">
            <hardwareInterface>hardware_interface/PositionJointInterface</hardwareInterface>
        </joint>
        <actuator name="motor6">
            <hardwareInterface>hardware_interface/PositionJointInterface</hardwareInterface>
            <mechanicalReduction>1</mechanicalReduction>
        </actuator>
    </transmission>
    <transmission name="transmission7">
        <type>transmission_interface/SimpleTransmission</type>
        <joint name="joint7">
            <hardwareInterface>hardware_interface/PositionJointInterface</hardwareInterface>
        </joint>
        <actuator name="motor7">
            <hardwareInterface>hardware_interface/PositionJointInterface</hardwareInterface>
            <mechanicalReduction>1</mechanicalReduction>
        </actuator>
    </transmission>
    <gazebo>
        <plugin filename="libgazebo_ros_control.so" name="gazebo_ros_control">
            <robotNamespace>/robot_arm</robotNamespace>
            <robotSimType>gazebo_ros_control/DefaultRobotHWSim</robotSimType>
            <legacyModeNS>true</legacyModeNS>
        </plugin>
        <plugin filename="libroroboticsgroup_gazebo_mimic_joint_plugin.so" name="joint7_mimic_joint6">
            <joint>joint6</joint>
            <mimicJoint>joint7</mimicJoint>
            <multiplier>-1.0</multiplier>
            <offset>0</offset>
            <maxEffort>30</maxEffort>
            <robotNamespace>/robot_arm</robotNamespace>
        </plugin>
    </gazebo>
</robot>

